<?xml version="1.0" ?>
<!-- =================================================================================== -->
<!-- |    This document was autogenerated by xacro from irb120.xacro                   | -->
<!-- |    EDITING THIS FILE BY HAND IS NOT RECOMMENDED                                 | -->
<!-- =================================================================================== -->
<robot name="abb_irb120" xmlns:xacro="http://ros.org/wiki/xacro">
  <!--  <xacro:include filename="$(find irb120_description)/urdf/common_colors.xacro"/> -->
  <!-- Conversion were obtained from http://www.e-paint.co.uk/Lab_values.asp
       unless otherwise stated. -->
  <!-- Actual colors -->
  <!-- NCS 2070-Y60R orange, standard robot color 1974 - May 2014 -->
  <!-- RAL 7035 light grey (abb graphite white), standard robot color May 2014 - current -->
  <!-- RAL 9003 signal white (abb white), cleanroom robot color -->
  <!-- RAL 7032 pebble gray, controller -->
  <!-- RAL 7012 basalt gray (abb dark gray) , robot primer -->
  <!-- RAL 7021 black gray (abb black) , robot with dark link color -->
  <!-- Other robot colours availble, but not limited too. -->
  <!-- RAL 3001 signal red -->
  <!-- RAL 3002 carmine red -->
  <!-- RAL 5002 ultramarine blue -->
  <!-- RAL 5015 sky blue -->
  <!-- RAL 6002 leaf green -->
  <!-- RAL 9002 gray white -->
  <!-- RAL 9010 pure white -->
  <!-- approximations -->
  <!-- yellow, collision model -->
  <!-- Used for fixing robot to Gazebo 'base_link' -->
  <link name="world"/>
  <joint name="fixed" type="fixed">
    <parent link="world"/>
    <child link="base_link"/>
    <origin rpy="0 0 0" xyz="0 0 0.76"/>
  </joint>
  <!-- Description of base_link -->
  <link name="base_link">
    <inertial>
      <mass value="6.215"/>
      <origin rpy="0 0 0" xyz="0 0 0"/>
      <inertia ixx="0.0247272" ixy="-8.0784E-05" ixz="0.00130902" iyy="0.0491285" iyz="-8.0419E-06" izz="0.0472376"/>
    </inertial>
    <visual>
      <origin rpy="0 0 0" xyz="0 0 0"/>
      <geometry>
        <mesh filename="package://irb120_description/meshes/visual/base_link.stl"/>
      </geometry>
      <material name="">
        <color rgba="0.7372549 0.3490196 0.1607843 1"/>
      </material>
    </visual>
    <collision>
      <origin rpy="0 0 0" xyz="0 0 0"/>
      <geometry>
        <mesh filename="package://irb120_description/meshes/collision/base_link.stl"/>
      </geometry>
      <material name="">
        <color rgba="1 1 0 1"/>
      </material>
    </collision>
  </link>
  <joint name="base_link-Table" type="fixed">
    <parent link="base_link"/>
    <child link="Table"/>
    <origin rpy="0 0 0" xyz="0 0 0"/>
  </joint>
  <link name="Table">
    <inertial>
      <origin rpy="0 0 0" xyz="0 0 -0.06"/>
      <mass value="26.973"/>
      <inertia ixx="1.58867585086805" ixy="7.53875576876204E-16" ixz="-1.555189911135E-16" iyy="-0.00481570948189264" iyz="-3.49190034458366" izz="0.00481570948189306"/>
    </inertial>
    <visual>
      <origin rpy="0 0 0" xyz="0 0 -0.06"/>
      <geometry>
        <mesh filename="package://irb120_description/meshes/visual/Table.STL"/>
      </geometry>
      <material name="">
        <color rgba="0.3450980 0.3647059 0.3686275 1"/>
      </material>
    </visual>
    <collision>
      <origin rpy="1.5707963267949 0 0" xyz="0 0 -0.06"/>
      <geometry>
        <mesh filename="package://irb120_description/meshes/collision/Table.STL"/>
      </geometry>
      <material name="">
        <color rgba="0.5960784 0.1372549 0.1372549 1"/>
      </material>
    </collision>
  </link>
  <joint name="Table-PCB" type="fixed">
    <parent link="Table"/>
    <child link="PCB"/>
    <origin rpy="0 0 0" xyz="0 0 0"/>
  </joint>
  <link name="PCB">
    <inertial>
      <origin rpy="0 0 0" xyz="3.0815E-19 -6.597E-07 -0.00020574"/>
      <mass value="0.011199"/>
      <inertia ixx="2.5416E-05" ixy="-1.4976E-21" ixz="-4.5523E-24" iyy="2.5392E-05" iyz="1.366E-23" izz="5.0808E-05"/>
    </inertial>
    <visual>
      <origin rpy="-1.57079632679 0 0" xyz="0.4 0 0.001"/>
      <geometry>
        <mesh filename="package://irb120_description/meshes/visual/PCB.STL"/>
      </geometry>
      <material name="green">
        <color rgba="0 0.5 0 1"/>
      </material>
    </visual>
    <collision>
      <origin rpy="0 0 0" xyz="0.4 0 0.001"/>
      <geometry>
        <mesh filename="package://irb120_description/meshes/collision/PCB.STL"/>
      </geometry>
    </collision>
  </link>
  <joint name="PCB-BGA_1" type="fixed">
    <parent link="PCB"/>
    <child link="BGA_1"/>
    <origin rpy="0 0 0" xyz="0 0 0"/>
  </joint>
  <link name="BGA_1">
    <inertial>
      <origin rpy="0 0 0" xyz="-0.05715 -0.00124 -0.05715"/>
      <mass value="0.0012696"/>
      <inertia ixx="5.6578E-08" ixy="-1.2683E-24" ixz="-4.2352E-24" iyy="1.1194E-07" iyz="3.3896E-24" izz="5.6578E-08"/>
    </inertial>
    <visual>
      <origin rpy="-1.57079632679 0 0" xyz="0.4 0 0.001"/>
      <geometry>
        <mesh filename="package://irb120_description/meshes/visual/BGA_1.STL"/>
      </geometry>
      <material name="white">
        <color rgba="1 1 1 1"/>
      </material>
    </visual>
    <collision>
      <origin rpy="0 0 0" xyz="0.4 0 0.001"/>
      <geometry>
        <mesh filename="package://irb120_description/meshes/collision/BGA_1.STL"/>
      </geometry>
    </collision>
  </link>
  <joint name="PCB-BGA_2" type="fixed">
    <parent link="PCB"/>
    <child link="BGA_2"/>
    <origin rpy="0 0 0" xyz="0 0 0"/>
  </joint>
  <link name="BGA_2">
    <inertial>
      <origin rpy="0 0 0" xyz="-0.01905 -0.00124 -0.05715"/>
      <mass value="0.0012696"/>
      <inertia ixx="5.6578E-08" ixy="-7.2405E-26" ixz="-2.0814E-22" iyy="1.1194E-07" iyz="2.587E-24" izz="5.6578E-08"/>
    </inertial>
    <visual>
      <origin rpy="-1.57079632679 0 0" xyz="0.4 0 0.001"/>
      <geometry>
        <mesh filename="package://irb120_description/meshes/visual/BGA_2.STL"/>
      </geometry>
      <material name="white">
        <color rgba="1 1 1 1"/>
      </material>
    </visual>
    <collision>
      <origin rpy="0 0 0" xyz="0.4 0 0.001"/>
      <geometry>
        <mesh filename="package://irb120_description/meshes/collision/BGA_2.STL"/>
      </geometry>
    </collision>
  </link>
  <joint name="PCB-BGA_3" type="fixed">
    <parent link="PCB"/>
    <child link="BGA_3"/>
    <origin rpy="0 0 0" xyz="0 0 0"/>
  </joint>
  <link name="BGA_3">
    <inertial>
      <origin rpy="0 0 0" xyz="0.01905 -0.00124 -0.05715"/>
      <mass value="0.0012696"/>
      <inertia ixx="5.6578E-08" ixy="-6.3417E-25" ixz="-6.7719E-24" iyy="1.1194E-07" iyz="3.3896E-24" izz="5.6578E-08"/>
    </inertial>
    <visual>
      <origin rpy="-1.57079632679 0 0" xyz="0.4 0 0.001"/>
      <geometry>
        <mesh filename="package://irb120_description/meshes/visual/BGA_3.STL"/>
      </geometry>
      <material name="white">
        <color rgba="1 1 1 1"/>
      </material>
    </visual>
    <collision>
      <origin rpy="0 0 0" xyz="0.4 0 0.001"/>
      <geometry>
        <mesh filename="package://irb120_description/meshes/collision/BGA_3.STL"/>
      </geometry>
    </collision>
  </link>
  <joint name="PCB-BGA_4" type="fixed">
    <parent link="PCB"/>
    <child link="BGA_4"/>
    <origin rpy="0 0 0" xyz="0 0 0"/>
  </joint>
  <link name="BGA_4">
    <inertial>
      <origin rpy="0 0 0" xyz="0.05715 -0.00124 -0.05715"/>
      <mass value="0.0012696"/>
      <inertia ixx="5.6578E-08" ixy="6.1225E-25" ixz="-2.3237E-22" iyy="1.1194E-07" iyz="2.9474E-24" izz="5.6578E-08"/>
    </inertial>
    <visual>
      <origin rpy="-1.57079632679 0 0" xyz="0.4 0 0.001"/>
      <geometry>
        <mesh filename="package://irb120_description/meshes/visual/BGA_4.STL"/>
      </geometry>
      <material name="white">
        <color rgba="1 1 1 1"/>
      </material>
    </visual>
    <collision>
      <origin rpy="0 0 0" xyz="0.4 0 0.001"/>
      <geometry>
        <mesh filename="package://irb120_description/meshes/collision/BGA_4.STL"/>
      </geometry>
    </collision>
  </link>
  <joint name="PCB-BGA_5" type="fixed">
    <parent link="PCB"/>
    <child link="BGA_5"/>
    <origin rpy="0 0 0" xyz="0 0 0"/>
  </joint>
  <link name="BGA_5">
    <inertial>
      <origin rpy="0 0 0" xyz="-0.05715 -0.01905 0.00068"/>
      <mass value="0.00014976"/>
      <inertia ixx="1.8106E-09" ixy="3.4411E-25" ixz="0" iyy="1.8106E-09" iyz="0" izz="3.5942E-09"/>
    </inertial>
    <visual>
      <origin rpy="-1.57079632679 0 0" xyz="0.4 0 0.001"/>
      <geometry>
        <mesh filename="package://irb120_description/meshes/visual/BGA_5.STL"/>
      </geometry>
      <material name="white">
        <color rgba="1 1 1 1"/>
      </material>
    </visual>
    <collision>
      <origin rpy="-1.57079632679 0 0" xyz="0.4 0 0.001"/>
      <geometry>
        <mesh filename="package://irb120_description/meshes/collision/BGA_5.STL"/>
      </geometry>
    </collision>
  </link>
  <joint name="PCB-BGA_6" type="fixed">
    <parent link="PCB"/>
    <child link="BGA_6"/>
    <origin rpy="0 0 0" xyz="0 0 0"/>
  </joint>
  <link name="BGA_6">
    <inertial>
      <origin rpy="0 0 0" xyz="-0.01905 -0.00068 -0.01905"/>
      <mass value="0.00014976"/>
      <inertia ixx="1.8106E-09" ixy="-2.0002E-27" ixz="-1.767E-25" iyy="3.5942E-09" iyz="1.1783E-25" izz="1.8106E-09"/>
    </inertial>
    <visual>
      <origin rpy="-1.57079632679 0 0" xyz="0.4 0 0.001"/>
      <geometry>
        <mesh filename="package://irb120_description/meshes/visual/BGA_6.STL"/>
      </geometry>
      <material name="white">
        <color rgba="1 1 1 1"/>
      </material>
    </visual>
    <collision>
      <origin rpy="-1.57079632679 0 0" xyz="0.4 0 0.001"/>
      <geometry>
        <mesh filename="package://irb120_description/meshes/collision/BGA_6.STL"/>
      </geometry>
    </collision>
  </link>
  <joint name="PCB-BGA_7" type="fixed">
    <parent link="PCB"/>
    <child link="BGA_7"/>
    <origin rpy="0 0 0" xyz="0 0 0"/>
  </joint>
  <link name="BGA_7">
    <inertial>
      <origin rpy="0 0 0" xyz="0.01905 -0.00068 -0.01905"/>
      <mass value="0.00014976"/>
      <inertia ixx="1.8106E-09" ixy="7.0233E-42" ixz="1.147E-25" iyy="3.5942E-09" iyz="1.0921E-25" izz="1.8106E-09"/>
    </inertial>
    <visual>
      <origin rpy="-1.57079632679 0 0" xyz="0.4 0 0.001"/>
      <geometry>
        <mesh filename="package://irb120_description/meshes/visual/BGA_7.STL"/>
      </geometry>
      <material name="white">
        <color rgba="1 1 1 1"/>
      </material>
    </visual>
    <collision>
      <origin rpy="-1.57079632679 0 0" xyz="0.4 0 0.001"/>
      <geometry>
        <mesh filename="package://irb120_description/meshes/collision/BGA_7.STL"/>
      </geometry>
    </collision>
  </link>
  <joint name="PCB-BGA_8" type="fixed">
    <parent link="PCB"/>
    <child link="BGA_8"/>
    <origin rpy="0 0 0" xyz="0 0 0"/>
  </joint>
  <link name="BGA_8">
    <inertial>
      <origin rpy="0 0 0" xyz="0.05715 -0.00068 -0.01905"/>
      <mass value="0.00014976"/>
      <inertia ixx="1.8106E-09" ixy="5.8884E-27" ixz="7.3206E-25" iyy="3.5942E-09" iyz="1.1783E-25" izz="1.8106E-09"/>
    </inertial>
    <visual>
      <origin rpy="-1.57079632679 0 0" xyz="0.4 0 0.001"/>
      <geometry>
        <mesh filename="package://irb120_description/meshes/visual/BGA_8.STL"/>
      </geometry>
      <material name="white">
        <color rgba="1 1 1 1"/>
      </material>
    </visual>
    <collision>
      <origin rpy="-1.57079632679 0 0" xyz="0.4 0 0.001"/>
      <geometry>
        <mesh filename="package://irb120_description/meshes/collision/BGA_8.STL"/>
      </geometry>
    </collision>
  </link>
  <joint name="PCB-BGA_9" type="fixed">
    <parent link="PCB"/>
    <child link="BGA_9"/>
    <origin rpy="0 0 0" xyz="0 0 0"/>
  </joint>
  <link name="BGA_9">
    <inertial>
      <origin rpy="0 0 0" xyz="-0.057151 -0.00063064 0.0063493"/>
      <mass value="3.7062E-05"/>
      <inertia ixx="1.5631E-10" ixy="-4.6839E-15" ixz="5.8399E-14" iyy="3.0916E-10" iyz="-4.4908E-15" izz="1.563E-10"/>
    </inertial>
    <visual>
      <origin rpy="-1.57079632679 0 0" xyz="0.4 0 0.001"/>
      <geometry>
        <mesh filename="package://irb120_description/meshes/visual/BGA_9.STL"/>
      </geometry>
      <material name="white">
        <color rgba="1 1 1 1"/>
      </material>
    </visual>
    <collision>
      <origin rpy="-1.57079632679 0 0" xyz="0.4 0 0.001"/>
      <geometry>
        <mesh filename="package://irb120_description/meshes/collision/BGA_9.STL"/>
      </geometry>
    </collision>
  </link>
  <joint name="PCB-BGA_10" type="fixed">
    <parent link="PCB"/>
    <child link="BGA_10"/>
    <origin rpy="0 0 0" xyz="0 0 0"/>
  </joint>
  <link name="BGA_10">
    <inertial>
      <origin rpy="0 0 0" xyz="-0.01905 -0.00063064 0.0063489"/>
      <mass value="3.7062E-05"/>
      <inertia ixx="1.5636E-10" ixy="-1.3834E-16" ixz="-6.9721E-16" iyy="3.0916E-10" iyz="-6.4853E-15" izz="1.5625E-10"/>
    </inertial>
    <visual>
      <origin rpy="-1.57079632679 0 0" xyz="0.4 0 0.001"/>
      <geometry>
        <mesh filename="package://irb120_description/meshes/visual/BGA_10.STL"/>
      </geometry>
      <material name="white">
        <color rgba="1 1 1 1"/>
      </material>
    </visual>
    <collision>
      <origin rpy="-1.57079632679 0 0" xyz="0.4 0 0.001"/>
      <geometry>
        <mesh filename="package://irb120_description/meshes/collision/BGA_10.STL"/>
      </geometry>
    </collision>
  </link>
  <joint name="PCB-BGA_11" type="fixed">
    <parent link="PCB"/>
    <child link="BGA_11"/>
    <origin rpy="0 0 0" xyz="0 0 0"/>
  </joint>
  <link name="BGA_11">
    <inertial>
      <origin rpy="0 0 0" xyz="0.019051 -0.00063064 0.0063491"/>
      <mass value="3.7062E-05"/>
      <inertia ixx="1.563E-10" ixy="4.4908E-15" ixz="-5.8399E-14" iyy="3.0916E-10" iyz="-4.6839E-15" izz="1.5631E-10"/>
    </inertial>
    <visual>
      <origin rpy="-1.57079632679 0 0" xyz="0.4 0 0.001"/>
      <geometry>
        <mesh filename="package://irb120_description/meshes/visual/BGA_11.STL"/>
      </geometry>
      <material name="white">
        <color rgba="1 1 1 1"/>
      </material>
    </visual>
    <collision>
      <origin rpy="-1.57079632679 0 0" xyz="0.4 0 0.001"/>
      <geometry>
        <mesh filename="package://irb120_description/meshes/collision/BGA_11.STL"/>
      </geometry>
    </collision>
  </link>
  <joint name="PCB-BGA_12" type="fixed">
    <parent link="PCB"/>
    <child link="BGA_12"/>
    <origin rpy="0 0 0" xyz="0 0 0"/>
  </joint>
  <link name="BGA_12">
    <inertial>
      <origin rpy="0 0 0" xyz="0.05715 -0.00063064 0.0063489"/>
      <mass value="3.7062E-05"/>
      <inertia ixx="1.5636E-10" ixy="-1.3834E-16" ixz="-6.9721E-16" iyy="3.0916E-10" iyz="-6.4853E-15" izz="1.5625E-10"/>
    </inertial>
    <visual>
      <origin rpy="-1.57079632679 0 0" xyz="0.4 0 0.001"/>
      <geometry>
        <mesh filename="package://irb120_description/meshes/visual/BGA_12.STL"/>
      </geometry>
      <material name="white">
        <color rgba="1 1 1 1"/>
      </material>
    </visual>
    <collision>
      <origin rpy="-1.57079632679 0 0" xyz="0.4 0 0.001"/>
      <geometry>
        <mesh filename="package://irb120_description/meshes/collision/BGA_12.STL"/>
      </geometry>
    </collision>
  </link>
  <joint name="PCB-BGA_13" type="fixed">
    <parent link="PCB"/>
    <child link="BGA_13"/>
    <origin rpy="0 0 0" xyz="0 0 0"/>
  </joint>
  <link name="BGA_13">
    <inertial>
      <origin rpy="0 0 0" xyz="-0.05715 -0.0006 0.03175"/>
      <mass value="5.88E-05"/>
      <inertia ixx="2.4716E-10" ixy="-3.0158E-27" ixz="-1.6544E-26" iyy="4.802E-10" iyz="1.7285E-26" izz="2.4716E-10"/>
    </inertial>
    <visual>
      <origin rpy="-1.57079632679 0 0" xyz="0.4 0 0.001"/>
      <geometry>
        <mesh filename="package://irb120_description/meshes/visual/BGA_13.STL"/>
      </geometry>
      <material name="white">
        <color rgba="1 1 1 1"/>
      </material>
    </visual>
    <collision>
      <origin rpy="0 0 0" xyz="0.4 0 0.001"/>
      <geometry>
        <mesh filename="package://irb120_description/meshes/collision/BGA_13.STL"/>
      </geometry>
    </collision>
  </link>
  <joint name="PCB-BGA_14" type="fixed">
    <parent link="PCB"/>
    <child link="BGA_14"/>
    <origin rpy="0 0 0.001" xyz="0 0 0"/>
  </joint>
  <link name="BGA_14">
    <inertial>
      <origin rpy="0 0 0" xyz="-0.01905 -0.0006 0.03175"/>
      <mass value="5.88E-05"/>
      <inertia ixx="2.4716E-10" ixy="7.4522E-27" ixz="9.4663E-27" iyy="4.802E-10" iyz="3.6443E-27" izz="2.4716E-10"/>
    </inertial>
    <visual>
      <origin rpy="-1.57079632679 0 0" xyz="0.4 0 0.001"/>
      <geometry>
        <mesh filename="package://irb120_description/meshes/visual/BGA_14.STL"/>
      </geometry>
      <material name="white">
        <color rgba="1 1 1 1"/>
      </material>
    </visual>
    <collision>
      <origin rpy="-1.57079632679 0 0" xyz="0.4 0 0.001"/>
      <geometry>
        <mesh filename="package://irb120_description/meshes/collision/BGA_14.STL"/>
      </geometry>
    </collision>
  </link>
  <joint name="PCB-BGA_15" type="fixed">
    <parent link="PCB"/>
    <child link="BGA_15"/>
    <origin rpy="0 0 0" xyz="0 0 0"/>
  </joint>
  <link name="BGA_15">
    <inertial>
      <origin rpy="0 0 0" xyz="0.01905 -0.0006 0.03175"/>
      <mass value="5.88E-05"/>
      <inertia ixx="2.4716E-10" ixy="-3.0158E-27" ixz="-1.6544E-26" iyy="4.802E-10" iyz="1.7285E-26" izz="2.4716E-10"/>
    </inertial>
    <visual>
      <origin rpy="-1.57079632679 0 0" xyz="0.4 0 0.001"/>
      <geometry>
        <mesh filename="package://irb120_description/meshes/visual/BGA_15.STL"/>
      </geometry>
      <material name="white">
        <color rgba="1 1 1 1"/>
      </material>
    </visual>
    <collision>
      <origin rpy="-1.57079632679 0 0" xyz="0.4 0 0.001"/>
      <geometry>
        <mesh filename="package://irb120_description/meshes/collision/BGA_15.STL"/>
      </geometry>
    </collision>
  </link>
  <joint name="PCB-BGA_16" type="fixed">
    <parent link="PCB"/>
    <child link="BGA_16"/>
    <origin rpy="0 0 0" xyz="0 0 0"/>
  </joint>
  <link name="BGA_16">
    <inertial>
      <origin rpy="0 0 0" xyz="0.05715 -0.0006 0.03175"/>
      <mass value="5.88E-05"/>
      <inertia ixx="2.4716E-10" ixy="4.7948E-27" ixz="3.1554E-27" iyy="4.802E-10" iyz="5.1522E-27" izz="2.4716E-10"/>
    </inertial>
    <visual>
      <origin rpy="-1.57079632679 0 0" xyz="0.4 0 0.001"/>
      <geometry>
        <mesh filename="package://irb120_description/meshes/visual/BGA_16.STL"/>
      </geometry>
      <material name="white">
        <color rgba="1 1 1 1"/>
      </material>
    </visual>
    <collision>
      <origin rpy="-1.57079632679 0 0" xyz="0.4 0 0.001"/>
      <geometry>
        <mesh filename="package://irb120_description/meshes/collision/BGA_16.STL"/>
      </geometry>
    </collision>
  </link>
  <!-- Joint - 1 -->
  <joint name="joint_1" type="revolute">
    <origin rpy="0 0 0" xyz="0 0 0"/>
    <parent link="base_link"/>
    <child link="link_1"/>
    <limit effort="20" lower="-2.87979" upper="2.87979" velocity="4.36332"/>
    <axis xyz="0 0 1"/>
    <dynamics damping="1" friction="0"/>
  </joint>
  <!-- Description of link - 1 -->
  <link name="link_1">
    <inertial>
      <mass value="3.067"/>
      <origin rpy="0 0 0" xyz="0 0 0.23841"/>
      <inertia ixx="0.0142175" ixy="-1.28579E-05" ixz="-2.31364E-05" iyy="0.0144041" iyz="1.93404E-05" izz="0.0104533"/>
    </inertial>
    <visual>
      <origin rpy="0 0 0" xyz="0 0 0"/>
      <geometry>
        <mesh filename="package://irb120_description/meshes/visual/link_1.stl"/>
      </geometry>
      <material name="">
        <color rgba="0.7372549 0.3490196 0.1607843 1"/>
      </material>
    </visual>
    <collision>
      <origin rpy="0 0 0" xyz="0 0 0"/>
      <geometry>
        <mesh filename="package://irb120_description/meshes/collision/link_1.stl"/>
      </geometry>
      <material name="">
        <color rgba="1 1 0 1"/>
      </material>
    </collision>
  </link>
  <!-- Joint - 2 -->
  <joint name="joint_2" type="revolute">
    <origin rpy="0 0 0" xyz="0 0 0.29"/>
    <parent link="link_1"/>
    <child link="link_2"/>
    <limit effort="20" lower="-1.91986" upper="1.91986" velocity="4.36332"/>
    <axis xyz="0 1 0"/>
    <dynamics damping="1" friction="0"/>
  </joint>
  <!-- Description of link - 2 -->
  <link name="link_2">
    <inertial>
      <mass value="3.909"/>
      <origin rpy="0 0 0" xyz="0.00078 -0.00212 0.10124"/>
      <inertia ixx="0.0603111" ixy="9.83431E-06" ixz="5.72407E-05" iyy="0.041569" iyz="-0.00050497" izz="0.0259548"/>
    </inertial>
    <visual>
      <origin rpy="0 0 0" xyz="0 0 0"/>
      <geometry>
        <mesh filename="package://irb120_description/meshes/visual/link_2.stl"/>
      </geometry>
      <material name="">
        <color rgba="0.7372549 0.3490196 0.1607843 1"/>
      </material>
    </visual>
    <collision>
      <origin rpy="0 0 0" xyz="0 0 0"/>
      <geometry>
        <mesh filename="package://irb120_description/meshes/collision/link_2.stl"/>
      </geometry>
      <material name="">
        <color rgba="1 1 0 1"/>
      </material>
    </collision>
  </link>
  <!-- Joint - 3 -->
  <joint name="joint_3" type="revolute">
    <origin rpy="0 0 0" xyz="0 0 0.27"/>
    <parent link="link_2"/>
    <child link="link_3"/>
    <limit effort="20" lower="-1.91986" upper="1.22173" velocity="4.36332"/>
    <axis xyz="0 1 0"/>
    <dynamics damping="0.7" friction="0.2"/>
  </joint>
  <!-- Description of link - 3 -->
  <link name="link_3">
    <inertial>
      <mass value="2.944"/>
      <origin rpy="0 0 0" xyz="0.02281 0.00106 0.05791"/>
      <inertia ixx="0.00835606" ixy="-8.01545E-05" ixz="0.00142884" iyy="0.016713" iyz="-0.000182227" izz="0.0126984"/>
    </inertial>
    <visual>
      <origin rpy="0 0 0" xyz="0 0 0"/>
      <geometry>
        <mesh filename="package://irb120_description/meshes/visual/link_3.stl"/>
      </geometry>
      <material name="">
        <color rgba="0.7372549 0.3490196 0.1607843 1"/>
      </material>
    </visual>
    <collision>
      <origin rpy="0 0 0" xyz="0 0 0"/>
      <geometry>
        <mesh filename="package://irb120_description/meshes/collision/link_3.stl"/>
      </geometry>
      <material name="">
        <color rgba="1 1 0 1"/>
      </material>
    </collision>
  </link>
  <!-- Joint - 4 -->
  <joint name="joint_4" type="revolute">
    <origin rpy="0 0 0" xyz="0 0 0.07"/>
    <parent link="link_3"/>
    <child link="link_4"/>
    <limit effort="20" lower="-2.79253" upper="2.79253" velocity="5.58505"/>
    <axis xyz="1 0 0"/>
    <dynamics damping="0.7" friction="0.2"/>
  </joint>
  <!--  Description of link - 4 -->
  <link name="link_4">
    <inertial>
      <mass value="1.328"/>
      <origin rpy="0 0 0" xyz="0.2247 0.00015 0.00041"/>
      <inertia ixx="0.00284661" ixy="-2.12765E-05" ixz="-1.6435E-05" iyy="0.00401346" iyz="1.31336E-05" izz="0.0052535"/>
    </inertial>
    <visual>
      <origin rpy="0 0 0" xyz="0 0 0"/>
      <geometry>
        <mesh filename="package://irb120_description/meshes/visual/link_4.stl"/>
      </geometry>
      <material name="">
        <color rgba="0.7372549 0.3490196 0.1607843 1"/>
      </material>
    </visual>
    <collision>
      <origin rpy="0 0 0" xyz="0 0 0"/>
      <geometry>
        <mesh filename="package://irb120_description/meshes/collision/link_4.stl"/>
      </geometry>
      <material name="">
        <color rgba="1 1 0 1"/>
      </material>
    </collision>
  </link>
  <!-- Joint - 5 -->
  <joint name="joint_5" type="revolute">
    <origin rpy="0 0 0" xyz="0.302 0 0"/>
    <parent link="link_4"/>
    <child link="link_5"/>
    <limit effort="20" lower="-2.094395" upper="2.094395" velocity="5.58505"/>
    <axis xyz="0 1 0"/>
    <dynamics damping="0.7" friction="0.2"/>
  </joint>
  <!-- Description of link - 5-->
  <link name="link_5">
    <inertial>
      <mass value="0.546"/>
      <origin rpy="0 0 0" xyz="-0.00109 3.68E-05 6.22E-05"/>
      <inertia ixx="0.000404891" ixy="1.61943E-06" ixz="8.46805E-07" iyy="0.000892825" iyz="-1.51792E-08" izz="0.000815468"/>
    </inertial>
    <visual>
      <origin rpy="0 0 0" xyz="0 0 0"/>
      <geometry>
        <mesh filename="package://irb120_description/meshes/visual/link_5.stl"/>
      </geometry>
      <material name="">
        <color rgba="0.7372549 0.3490196 0.1607843 1"/>
      </material>
    </visual>
    <collision>
      <origin rpy="0 0 0" xyz="0 0 0"/>
      <geometry>
        <mesh filename="package://irb120_description/meshes/collision/link_5.stl"/>
      </geometry>
      <material name="">
        <color rgba="1 1 0 1"/>
      </material>
    </collision>
  </link>
  <!-- Joint - 6 -->
  <joint name="joint_6" type="revolute">
    <origin rpy="0 0 0" xyz="0.072 0 0"/>
    <parent link="link_5"/>
    <child link="link_6"/>
    <limit effort="20" lower="-6.98132" upper="6.98132" velocity="7.33038"/>
    <axis xyz="1 0 0"/>
    <dynamics damping="0.7" friction="0.2"/>
  </joint>
  <!-- Description of link - 6 -->
  <link name="link_6">
    <inertial>
      <mass value="0.137"/>
      <origin rpy="0 0 0" xyz="-0.00706 -0.00017 -1.32E-06"/>
      <inertia ixx="0.001" ixy="0" ixz="0" iyy="0.001" iyz="0" izz="0.001"/>
    </inertial>
    <visual>
      <origin rpy="0 0 0" xyz="0 0 0"/>
      <geometry>
        <mesh filename="package://irb120_description/meshes/visual/link_6.stl"/>
      </geometry>
      <material name="">
        <color rgba="0.1882353 0.1960784 0.2039216 1"/>
      </material>
    </visual>
    <collision>
      <origin rpy="0 0 0" xyz="0 0 0"/>
      <geometry>
        <mesh filename="package://irb120_description/meshes/collision/link_6.stl"/>
      </geometry>
      <material name="">
        <color rgba="1 1 0 1"/>
      </material>
    </collision>
  </link>
  <!-- joint - 6 ___ end_effector -->
  <joint name="joint6-end_effector" type="fixed">
    <parent link="link_6"/>
    <child link="end_effector"/>
    <origin rpy="0 0 0" xyz="0 0 0"/>
  </joint>
  <!-- Description of end_effector -->
  <link name="end_effector">
    <inertial>
      <origin rpy="-1.57079632679 0 1.57079632679" xyz="0 0 0"/>
      <mass value="0.013866"/>
      <inertia ixx="5.03881484019862E-06" ixy="-1.04903875807579E-22" ixz="-4.65181001996142E-07" iyy="2.47955280107711E-22" iyz="-3.73495091382511E-06" izz="3.98009823013222E-22"/>
    </inertial>
    <visual>
      <origin rpy="-1.57079632679 0 1.57079632679" xyz="0 0 0"/>
      <geometry>
        <mesh filename="package://irb120_description/meshes/visual/EndEffector.SLDPRT.STL"/>
      </geometry>
      <material name="">
        <color rgba="1 1 0 1"/>
      </material>
    </visual>
    <collision>
      <origin rpy="-1.57079632679 0 1.57079632679" xyz="0 0 0"/>
      <geometry>
        <mesh filename="package://irb120_description/meshes/collision/EndEffector.SLDPRT.STL"/>
      </geometry>
      <material name="">
        <color rgba="0.5960784 0.1333333 0.1333333 1"/>
      </material>
    </collision>
  </link>
  <!-- end_effector ____ end_frame -->
  <joint name="end_effector-endframe" type="fixed">
    <parent link="end_effector"/>
    <child link="end_frame"/>
    <origin rpy="0 0 0" xyz="0.068 -0.01 0"/>
  </joint>
  <!-- Description of end_frame -->
  <link name="end_frame"/>
  <!-- end_effector ____ camera_frame -->
  <joint name="end_effector-cameraframe" type="fixed">
    <parent link="end_effector"/>
    <child link="camera_frame"/>
    <origin rpy="0 0 0" xyz="0.043 0.225 0"/>
  </joint>
  <!-- Description of camera_frame -->
  <link name="camera_frame"/>
  <transmission name="tran1">
    <type>transmission_interface/SimpleTransmission</type>
    <joint name="joint_1">
      <hardwareInterface>EffortJointInterface</hardwareInterface>
    </joint>
    <actuator name="motor1">
      <hardwareInterface>EffortJointInterface</hardwareInterface>
      <mechanicalReduction>1</mechanicalReduction>
    </actuator>
  </transmission>
  <transmission name="tran2">
    <type>transmission_interface/SimpleTransmission</type>
    <joint name="joint_2">
      <hardwareInterface>EffortJointInterface</hardwareInterface>
    </joint>
    <actuator name="motor2">
      <hardwareInterface>EffortJointInterface</hardwareInterface>
      <mechanicalReduction>1</mechanicalReduction>
    </actuator>
  </transmission>
  <transmission name="tran3">
    <type>transmission_interface/SimpleTransmission</type>
    <joint name="joint_3">
      <hardwareInterface>EffortJointInterface</hardwareInterface>
    </joint>
    <actuator name="motor3">
      <hardwareInterface>EffortJointInterface</hardwareInterface>
      <mechanicalReduction>1</mechanicalReduction>
    </actuator>
  </transmission>
  <transmission name="tran4">
    <type>transmission_interface/SimpleTransmission</type>
    <joint name="joint_4">
      <hardwareInterface>EffortJointInterface</hardwareInterface>
    </joint>
    <actuator name="motor4">
      <hardwareInterface>EffortJointInterface</hardwareInterface>
      <mechanicalReduction>1</mechanicalReduction>
    </actuator>
  </transmission>
  <transmission name="tran5">
    <type>transmission_interface/SimpleTransmission</type>
    <joint name="joint_5">
      <hardwareInterface>EffortJointInterface</hardwareInterface>
    </joint>
    <actuator name="motor5">
      <hardwareInterface>EffortJointInterface</hardwareInterface>
      <mechanicalReduction>1</mechanicalReduction>
    </actuator>
  </transmission>
  <transmission name="tran6">
    <type>transmission_interface/SimpleTransmission</type>
    <joint name="joint_6">
      <hardwareInterface>EffortJointInterface</hardwareInterface>
    </joint>
    <actuator name="motor6">
      <hardwareInterface>EffortJointInterface</hardwareInterface>
      <mechanicalReduction>1</mechanicalReduction>
    </actuator>
  </transmission>
  <!-- Gazebo-specific link properties -->
  <gazebo reference="base_link">
    <material>Gazebo/Orange</material>
    <turnGravityOff>true</turnGravityOff>
  </gazebo>
  <gazebo reference="link_1">
    <material>Gazebo/Orange</material>
    <turnGravityOff>true</turnGravityOff>
  </gazebo>
  <gazebo reference="link_2">
    <material>Gazebo/Orange</material>
    <turnGravityOff>true</turnGravityOff>
  </gazebo>
  <gazebo reference="link_3">
    <material>Gazebo/Orange</material>
    <turnGravityOff>true</turnGravityOff>
  </gazebo>
  <gazebo reference="link_4">
    <material>Gazebo/Orange</material>
    <turnGravityOff>true</turnGravityOff>
  </gazebo>
  <gazebo reference="link_5">
    <material>Gazebo/Orange</material>
    <turnGravityOff>true</turnGravityOff>
  </gazebo>
  <gazebo reference="link_6">
    <material>Gazebo/Black</material>
    <turnGravityOff>true</turnGravityOff>
  </gazebo>
  <gazebo reference="Table">
    <material>Gazebo/WoodPallet</material>
    <turnGravityOff>true</turnGravityOff>
  </gazebo>
  <gazebo reference="PCB">
    <material>Gazebo/Green</material>
    <turnGravityOff>true</turnGravityOff>
  </gazebo>
  <gazebo reference="BGA_1">
    <material>Gazebo/White</material>
    <turnGravityOff>true</turnGravityOff>
  </gazebo>
  <gazebo reference="BGA_2">
    <material>Gazebo/White</material>
    <turnGravityOff>true</turnGravityOff>
  </gazebo>
  <gazebo reference="BGA_3">
    <material>Gazebo/White</material>
    <turnGravityOff>true</turnGravityOff>
  </gazebo>
  <gazebo reference="BGA_4">
    <material>Gazebo/White</material>
    <turnGravityOff>true</turnGravityOff>
  </gazebo>
  <gazebo reference="BGA_5">
    <material>Gazebo/White</material>
    <turnGravityOff>true</turnGravityOff>
  </gazebo>
  <gazebo reference="BGA_6">
    <material>Gazebo/White</material>
    <turnGravityOff>true</turnGravityOff>
  </gazebo>
  <gazebo reference="BGA_7">
    <material>Gazebo/White</material>
    <turnGravityOff>true</turnGravityOff>
  </gazebo>
  <gazebo reference="BGA_8">
    <material>Gazebo/White</material>
    <turnGravityOff>true</turnGravityOff>
  </gazebo>
  <gazebo reference="BGA_9">
    <material>Gazebo/White</material>
    <turnGravityOff>true</turnGravityOff>
  </gazebo>
  <gazebo reference="BGA_10">
    <material>Gazebo/White</material>
    <turnGravityOff>true</turnGravityOff>
  </gazebo>
  <gazebo reference="BGA_11">
    <material>Gazebo/White</material>
    <turnGravityOff>true</turnGravityOff>
  </gazebo>
  <gazebo reference="BGA_12">
    <material>Gazebo/White</material>
    <turnGravityOff>true</turnGravityOff>
  </gazebo>
  <gazebo reference="BGA_13">
    <material>Gazebo/White</material>
    <turnGravityOff>true</turnGravityOff>
  </gazebo>
  <gazebo reference="BGA_14">
    <material>Gazebo/White</material>
    <turnGravityOff>true</turnGravityOff>
  </gazebo>
  <gazebo reference="BGA_15">
    <material>Gazebo/White</material>
    <turnGravityOff>true</turnGravityOff>
  </gazebo>
  <gazebo reference="BGA_16">
    <material>Gazebo/White</material>
    <turnGravityOff>true</turnGravityOff>
  </gazebo>
  <gazebo reference="end_effector">
    <material>Gazebo/Yellow</material>
    <turnGravityOff>true</turnGravityOff>
  </gazebo>
  <!-- ros_control plugin -->
  <gazebo>
    <plugin filename="libgazebo_ros_control.so" name="gazebo_ros_control">
      <robotNamespace>/irb120</robotNamespace>
      <robotSimType>gazebo_ros_control/DefaultRobotHWSim</robotSimType>
    </plugin>
  </gazebo>
</robot>

